{
  "experiment_id": "20250903_150004",
  "timestamp": "2025-09-03T15:00:24.044644",
  "results": {
    "bce_baseline": {
      "success": false,
      "error": "Training failed (code 1)",
      "stdout": "",
      "stderr": "on3': [Errno 2] No such file or directory\nE0903 15:00:08.156000 140673783443456 torch/distributed/elastic/multiprocessing/api.py:826] failed (exitcode: 2) local_rank: 0 (pid: 345875) of binary: /usr/bin/python3\nTraceback (most recent call last):\n  File \"/usr/local/bin/accelerate\", line 7, in <module>\n    sys.exit(main())\n  File \"/usr/local/lib/python3.10/dist-packages/accelerate/commands/accelerate_cli.py\", line 50, in main\n    args.func(args)\n  File \"/usr/local/lib/python3.10/dist-packages/accelerate/commands/launch.py\", line 1226, in launch_command\n    multi_gpu_launcher(args)\n  File \"/usr/local/lib/python3.10/dist-packages/accelerate/commands/launch.py\", line 853, in multi_gpu_launcher\n    distrib_run.run(args)\n  File \"/usr/local/lib/python3.10/dist-packages/torch/distributed/run.py\", line 870, in run\n    elastic_launch(\n  File \"/usr/local/lib/python3.10/dist-packages/torch/distributed/launcher/api.py\", line 132, in __call__\n    return launch_agent(self._config, self._entrypoint, list(args))\n  File \"/usr/local/lib/python3.10/dist-packages/torch/distributed/launcher/api.py\", line 263, in launch_agent\n    raise ChildFailedError(\ntorch.distributed.elastic.multiprocessing.errors.ChildFailedError: \n============================================================\npython3 FAILED\n------------------------------------------------------------\nFailures:\n[1]:\n  time      : 2025-09-03_15:00:08\n  host      : 2fd62b2353f7\n  rank      : 1 (local_rank: 1)\n  exitcode  : 2 (pid: 345876)\n  error_file: <N/A>\n  traceback : To enable traceback see: https://pytorch.org/docs/stable/elastic/errors.html\n------------------------------------------------------------\nRoot Cause (first observed failure):\n[0]:\n  time      : 2025-09-03_15:00:08\n  host      : 2fd62b2353f7\n  rank      : 0 (local_rank: 0)\n  exitcode  : 2 (pid: 345875)\n  error_file: <N/A>\n  traceback : To enable traceback see: https://pytorch.org/docs/stable/elastic/errors.html\n============================================================\n"
    },
    "asymmetric_loss": {
      "success": false,
      "error": "Training failed (code 1)",
      "stdout": "",
      "stderr": "on3': [Errno 2] No such file or directory\nE0903 15:00:11.998000 140533311488000 torch/distributed/elastic/multiprocessing/api.py:826] failed (exitcode: 2) local_rank: 0 (pid: 346059) of binary: /usr/bin/python3\nTraceback (most recent call last):\n  File \"/usr/local/bin/accelerate\", line 7, in <module>\n    sys.exit(main())\n  File \"/usr/local/lib/python3.10/dist-packages/accelerate/commands/accelerate_cli.py\", line 50, in main\n    args.func(args)\n  File \"/usr/local/lib/python3.10/dist-packages/accelerate/commands/launch.py\", line 1226, in launch_command\n    multi_gpu_launcher(args)\n  File \"/usr/local/lib/python3.10/dist-packages/accelerate/commands/launch.py\", line 853, in multi_gpu_launcher\n    distrib_run.run(args)\n  File \"/usr/local/lib/python3.10/dist-packages/torch/distributed/run.py\", line 870, in run\n    elastic_launch(\n  File \"/usr/local/lib/python3.10/dist-packages/torch/distributed/launcher/api.py\", line 132, in __call__\n    return launch_agent(self._config, self._entrypoint, list(args))\n  File \"/usr/local/lib/python3.10/dist-packages/torch/distributed/launcher/api.py\", line 263, in launch_agent\n    raise ChildFailedError(\ntorch.distributed.elastic.multiprocessing.errors.ChildFailedError: \n============================================================\npython3 FAILED\n------------------------------------------------------------\nFailures:\n[1]:\n  time      : 2025-09-03_15:00:11\n  host      : 2fd62b2353f7\n  rank      : 1 (local_rank: 1)\n  exitcode  : 2 (pid: 346060)\n  error_file: <N/A>\n  traceback : To enable traceback see: https://pytorch.org/docs/stable/elastic/errors.html\n------------------------------------------------------------\nRoot Cause (first observed failure):\n[0]:\n  time      : 2025-09-03_15:00:11\n  host      : 2fd62b2353f7\n  rank      : 0 (local_rank: 0)\n  exitcode  : 2 (pid: 346059)\n  error_file: <N/A>\n  traceback : To enable traceback see: https://pytorch.org/docs/stable/elastic/errors.html\n============================================================\n"
    },
    "combined_loss_07": {
      "success": false,
      "error": "Training failed (code 1)",
      "stdout": "",
      "stderr": "on3': [Errno 2] No such file or directory\nE0903 15:00:15.866000 140385755967488 torch/distributed/elastic/multiprocessing/api.py:826] failed (exitcode: 2) local_rank: 0 (pid: 346203) of binary: /usr/bin/python3\nTraceback (most recent call last):\n  File \"/usr/local/bin/accelerate\", line 7, in <module>\n    sys.exit(main())\n  File \"/usr/local/lib/python3.10/dist-packages/accelerate/commands/accelerate_cli.py\", line 50, in main\n    args.func(args)\n  File \"/usr/local/lib/python3.10/dist-packages/accelerate/commands/launch.py\", line 1226, in launch_command\n    multi_gpu_launcher(args)\n  File \"/usr/local/lib/python3.10/dist-packages/accelerate/commands/launch.py\", line 853, in multi_gpu_launcher\n    distrib_run.run(args)\n  File \"/usr/local/lib/python3.10/dist-packages/torch/distributed/run.py\", line 870, in run\n    elastic_launch(\n  File \"/usr/local/lib/python3.10/dist-packages/torch/distributed/launcher/api.py\", line 132, in __call__\n    return launch_agent(self._config, self._entrypoint, list(args))\n  File \"/usr/local/lib/python3.10/dist-packages/torch/distributed/launcher/api.py\", line 263, in launch_agent\n    raise ChildFailedError(\ntorch.distributed.elastic.multiprocessing.errors.ChildFailedError: \n============================================================\npython3 FAILED\n------------------------------------------------------------\nFailures:\n[1]:\n  time      : 2025-09-03_15:00:15\n  host      : 2fd62b2353f7\n  rank      : 1 (local_rank: 1)\n  exitcode  : 2 (pid: 346204)\n  error_file: <N/A>\n  traceback : To enable traceback see: https://pytorch.org/docs/stable/elastic/errors.html\n------------------------------------------------------------\nRoot Cause (first observed failure):\n[0]:\n  time      : 2025-09-03_15:00:15\n  host      : 2fd62b2353f7\n  rank      : 0 (local_rank: 0)\n  exitcode  : 2 (pid: 346203)\n  error_file: <N/A>\n  traceback : To enable traceback see: https://pytorch.org/docs/stable/elastic/errors.html\n============================================================\n"
    },
    "combined_loss_05": {
      "success": false,
      "error": "Training failed (code 1)",
      "stdout": "",
      "stderr": "on3': [Errno 2] No such file or directory\nE0903 15:00:19.716000 139939150331904 torch/distributed/elastic/multiprocessing/api.py:826] failed (exitcode: 2) local_rank: 0 (pid: 346308) of binary: /usr/bin/python3\nTraceback (most recent call last):\n  File \"/usr/local/bin/accelerate\", line 7, in <module>\n    sys.exit(main())\n  File \"/usr/local/lib/python3.10/dist-packages/accelerate/commands/accelerate_cli.py\", line 50, in main\n    args.func(args)\n  File \"/usr/local/lib/python3.10/dist-packages/accelerate/commands/launch.py\", line 1226, in launch_command\n    multi_gpu_launcher(args)\n  File \"/usr/local/lib/python3.10/dist-packages/accelerate/commands/launch.py\", line 853, in multi_gpu_launcher\n    distrib_run.run(args)\n  File \"/usr/local/lib/python3.10/dist-packages/torch/distributed/run.py\", line 870, in run\n    elastic_launch(\n  File \"/usr/local/lib/python3.10/dist-packages/torch/distributed/launcher/api.py\", line 132, in __call__\n    return launch_agent(self._config, self._entrypoint, list(args))\n  File \"/usr/local/lib/python3.10/dist-packages/torch/distributed/launcher/api.py\", line 263, in launch_agent\n    raise ChildFailedError(\ntorch.distributed.elastic.multiprocessing.errors.ChildFailedError: \n============================================================\npython3 FAILED\n------------------------------------------------------------\nFailures:\n[1]:\n  time      : 2025-09-03_15:00:19\n  host      : 2fd62b2353f7\n  rank      : 1 (local_rank: 1)\n  exitcode  : 2 (pid: 346309)\n  error_file: <N/A>\n  traceback : To enable traceback see: https://pytorch.org/docs/stable/elastic/errors.html\n------------------------------------------------------------\nRoot Cause (first observed failure):\n[0]:\n  time      : 2025-09-03_15:00:19\n  host      : 2fd62b2353f7\n  rank      : 0 (local_rank: 0)\n  exitcode  : 2 (pid: 346308)\n  error_file: <N/A>\n  traceback : To enable traceback see: https://pytorch.org/docs/stable/elastic/errors.html\n============================================================\n"
    },
    "combined_loss_03": {
      "success": false,
      "error": "Training failed (code 1)",
      "stdout": "",
      "stderr": "on3': [Errno 2] No such file or directory\nE0903 15:00:23.559000 139754336395264 torch/distributed/elastic/multiprocessing/api.py:826] failed (exitcode: 2) local_rank: 0 (pid: 346422) of binary: /usr/bin/python3\nTraceback (most recent call last):\n  File \"/usr/local/bin/accelerate\", line 7, in <module>\n    sys.exit(main())\n  File \"/usr/local/lib/python3.10/dist-packages/accelerate/commands/accelerate_cli.py\", line 50, in main\n    args.func(args)\n  File \"/usr/local/lib/python3.10/dist-packages/accelerate/commands/launch.py\", line 1226, in launch_command\n    multi_gpu_launcher(args)\n  File \"/usr/local/lib/python3.10/dist-packages/accelerate/commands/launch.py\", line 853, in multi_gpu_launcher\n    distrib_run.run(args)\n  File \"/usr/local/lib/python3.10/dist-packages/torch/distributed/run.py\", line 870, in run\n    elastic_launch(\n  File \"/usr/local/lib/python3.10/dist-packages/torch/distributed/launcher/api.py\", line 132, in __call__\n    return launch_agent(self._config, self._entrypoint, list(args))\n  File \"/usr/local/lib/python3.10/dist-packages/torch/distributed/launcher/api.py\", line 263, in launch_agent\n    raise ChildFailedError(\ntorch.distributed.elastic.multiprocessing.errors.ChildFailedError: \n============================================================\npython3 FAILED\n------------------------------------------------------------\nFailures:\n[1]:\n  time      : 2025-09-03_15:00:23\n  host      : 2fd62b2353f7\n  rank      : 1 (local_rank: 1)\n  exitcode  : 2 (pid: 346423)\n  error_file: <N/A>\n  traceback : To enable traceback see: https://pytorch.org/docs/stable/elastic/errors.html\n------------------------------------------------------------\nRoot Cause (first observed failure):\n[0]:\n  time      : 2025-09-03_15:00:23\n  host      : 2fd62b2353f7\n  rank      : 0 (local_rank: 0)\n  exitcode  : 2 (pid: 346422)\n  error_file: <N/A>\n  traceback : To enable traceback see: https://pytorch.org/docs/stable/elastic/errors.html\n============================================================\n"
    }
  }
}