{
  "experiment_id": "20250903_141734",
  "timestamp": "2025-09-03T14:17:49.835699",
  "results": {
    "bce_baseline": {
      "success": false,
      "error": "Training failed (code 1)",
      "stdout": "",
      "stderr": " [Errno 2] No such file or directory\nE0903 14:17:36.992000 140378196391744 torch/distributed/elastic/multiprocessing/api.py:826] failed (exitcode: 2) local_rank: 0 (pid: 311668) of binary: /venv/main/bin/python\nTraceback (most recent call last):\n  File \"/venv/main/bin/accelerate\", line 8, in <module>\n    sys.exit(main())\n  File \"/venv/main/lib/python3.10/site-packages/accelerate/commands/accelerate_cli.py\", line 48, in main\n    args.func(args)\n  File \"/venv/main/lib/python3.10/site-packages/accelerate/commands/launch.py\", line 1088, in launch_command\n    multi_gpu_launcher(args)\n  File \"/venv/main/lib/python3.10/site-packages/accelerate/commands/launch.py\", line 733, in multi_gpu_launcher\n    distrib_run.run(args)\n  File \"/venv/main/lib/python3.10/site-packages/torch/distributed/run.py\", line 870, in run\n    elastic_launch(\n  File \"/venv/main/lib/python3.10/site-packages/torch/distributed/launcher/api.py\", line 132, in __call__\n    return launch_agent(self._config, self._entrypoint, list(args))\n  File \"/venv/main/lib/python3.10/site-packages/torch/distributed/launcher/api.py\", line 263, in launch_agent\n    raise ChildFailedError(\ntorch.distributed.elastic.multiprocessing.errors.ChildFailedError: \n============================================================\npython3 FAILED\n------------------------------------------------------------\nFailures:\n[1]:\n  time      : 2025-09-03_14:17:36\n  host      : 2fd62b2353f7\n  rank      : 1 (local_rank: 1)\n  exitcode  : 2 (pid: 311669)\n  error_file: <N/A>\n  traceback : To enable traceback see: https://pytorch.org/docs/stable/elastic/errors.html\n------------------------------------------------------------\nRoot Cause (first observed failure):\n[0]:\n  time      : 2025-09-03_14:17:36\n  host      : 2fd62b2353f7\n  rank      : 0 (local_rank: 0)\n  exitcode  : 2 (pid: 311668)\n  error_file: <N/A>\n  traceback : To enable traceback see: https://pytorch.org/docs/stable/elastic/errors.html\n============================================================\n"
    },
    "asymmetric_loss": {
      "success": false,
      "error": "Training failed (code 1)",
      "stdout": "",
      "stderr": " [Errno 2] No such file or directory\nE0903 14:17:40.046000 139995269261120 torch/distributed/elastic/multiprocessing/api.py:826] failed (exitcode: 2) local_rank: 0 (pid: 311711) of binary: /venv/main/bin/python\nTraceback (most recent call last):\n  File \"/venv/main/bin/accelerate\", line 8, in <module>\n    sys.exit(main())\n  File \"/venv/main/lib/python3.10/site-packages/accelerate/commands/accelerate_cli.py\", line 48, in main\n    args.func(args)\n  File \"/venv/main/lib/python3.10/site-packages/accelerate/commands/launch.py\", line 1088, in launch_command\n    multi_gpu_launcher(args)\n  File \"/venv/main/lib/python3.10/site-packages/accelerate/commands/launch.py\", line 733, in multi_gpu_launcher\n    distrib_run.run(args)\n  File \"/venv/main/lib/python3.10/site-packages/torch/distributed/run.py\", line 870, in run\n    elastic_launch(\n  File \"/venv/main/lib/python3.10/site-packages/torch/distributed/launcher/api.py\", line 132, in __call__\n    return launch_agent(self._config, self._entrypoint, list(args))\n  File \"/venv/main/lib/python3.10/site-packages/torch/distributed/launcher/api.py\", line 263, in launch_agent\n    raise ChildFailedError(\ntorch.distributed.elastic.multiprocessing.errors.ChildFailedError: \n============================================================\npython3 FAILED\n------------------------------------------------------------\nFailures:\n[1]:\n  time      : 2025-09-03_14:17:40\n  host      : 2fd62b2353f7\n  rank      : 1 (local_rank: 1)\n  exitcode  : 2 (pid: 311712)\n  error_file: <N/A>\n  traceback : To enable traceback see: https://pytorch.org/docs/stable/elastic/errors.html\n------------------------------------------------------------\nRoot Cause (first observed failure):\n[0]:\n  time      : 2025-09-03_14:17:40\n  host      : 2fd62b2353f7\n  rank      : 0 (local_rank: 0)\n  exitcode  : 2 (pid: 311711)\n  error_file: <N/A>\n  traceback : To enable traceback see: https://pytorch.org/docs/stable/elastic/errors.html\n============================================================\n"
    },
    "combined_loss_07": {
      "success": false,
      "error": "Training failed (code 1)",
      "stdout": "",
      "stderr": " [Errno 2] No such file or directory\nE0903 14:17:43.093000 139621698131776 torch/distributed/elastic/multiprocessing/api.py:826] failed (exitcode: 2) local_rank: 0 (pid: 311983) of binary: /venv/main/bin/python\nTraceback (most recent call last):\n  File \"/venv/main/bin/accelerate\", line 8, in <module>\n    sys.exit(main())\n  File \"/venv/main/lib/python3.10/site-packages/accelerate/commands/accelerate_cli.py\", line 48, in main\n    args.func(args)\n  File \"/venv/main/lib/python3.10/site-packages/accelerate/commands/launch.py\", line 1088, in launch_command\n    multi_gpu_launcher(args)\n  File \"/venv/main/lib/python3.10/site-packages/accelerate/commands/launch.py\", line 733, in multi_gpu_launcher\n    distrib_run.run(args)\n  File \"/venv/main/lib/python3.10/site-packages/torch/distributed/run.py\", line 870, in run\n    elastic_launch(\n  File \"/venv/main/lib/python3.10/site-packages/torch/distributed/launcher/api.py\", line 132, in __call__\n    return launch_agent(self._config, self._entrypoint, list(args))\n  File \"/venv/main/lib/python3.10/site-packages/torch/distributed/launcher/api.py\", line 263, in launch_agent\n    raise ChildFailedError(\ntorch.distributed.elastic.multiprocessing.errors.ChildFailedError: \n============================================================\npython3 FAILED\n------------------------------------------------------------\nFailures:\n[1]:\n  time      : 2025-09-03_14:17:43\n  host      : 2fd62b2353f7\n  rank      : 1 (local_rank: 1)\n  exitcode  : 2 (pid: 311984)\n  error_file: <N/A>\n  traceback : To enable traceback see: https://pytorch.org/docs/stable/elastic/errors.html\n------------------------------------------------------------\nRoot Cause (first observed failure):\n[0]:\n  time      : 2025-09-03_14:17:43\n  host      : 2fd62b2353f7\n  rank      : 0 (local_rank: 0)\n  exitcode  : 2 (pid: 311983)\n  error_file: <N/A>\n  traceback : To enable traceback see: https://pytorch.org/docs/stable/elastic/errors.html\n============================================================\n"
    },
    "combined_loss_05": {
      "success": false,
      "error": "Training failed (code 1)",
      "stdout": "",
      "stderr": " [Errno 2] No such file or directory\nE0903 14:17:46.209000 139796578993984 torch/distributed/elastic/multiprocessing/api.py:826] failed (exitcode: 2) local_rank: 0 (pid: 312191) of binary: /venv/main/bin/python\nTraceback (most recent call last):\n  File \"/venv/main/bin/accelerate\", line 8, in <module>\n    sys.exit(main())\n  File \"/venv/main/lib/python3.10/site-packages/accelerate/commands/accelerate_cli.py\", line 48, in main\n    args.func(args)\n  File \"/venv/main/lib/python3.10/site-packages/accelerate/commands/launch.py\", line 1088, in launch_command\n    multi_gpu_launcher(args)\n  File \"/venv/main/lib/python3.10/site-packages/accelerate/commands/launch.py\", line 733, in multi_gpu_launcher\n    distrib_run.run(args)\n  File \"/venv/main/lib/python3.10/site-packages/torch/distributed/run.py\", line 870, in run\n    elastic_launch(\n  File \"/venv/main/lib/python3.10/site-packages/torch/distributed/launcher/api.py\", line 132, in __call__\n    return launch_agent(self._config, self._entrypoint, list(args))\n  File \"/venv/main/lib/python3.10/site-packages/torch/distributed/launcher/api.py\", line 263, in launch_agent\n    raise ChildFailedError(\ntorch.distributed.elastic.multiprocessing.errors.ChildFailedError: \n============================================================\npython3 FAILED\n------------------------------------------------------------\nFailures:\n[1]:\n  time      : 2025-09-03_14:17:46\n  host      : 2fd62b2353f7\n  rank      : 1 (local_rank: 1)\n  exitcode  : 2 (pid: 312192)\n  error_file: <N/A>\n  traceback : To enable traceback see: https://pytorch.org/docs/stable/elastic/errors.html\n------------------------------------------------------------\nRoot Cause (first observed failure):\n[0]:\n  time      : 2025-09-03_14:17:46\n  host      : 2fd62b2353f7\n  rank      : 0 (local_rank: 0)\n  exitcode  : 2 (pid: 312191)\n  error_file: <N/A>\n  traceback : To enable traceback see: https://pytorch.org/docs/stable/elastic/errors.html\n============================================================\n"
    },
    "combined_loss_03": {
      "success": false,
      "error": "Training failed (code 1)",
      "stdout": "",
      "stderr": " [Errno 2] No such file or directory\nE0903 14:17:49.313000 140537110304576 torch/distributed/elastic/multiprocessing/api.py:826] failed (exitcode: 2) local_rank: 0 (pid: 312306) of binary: /venv/main/bin/python\nTraceback (most recent call last):\n  File \"/venv/main/bin/accelerate\", line 8, in <module>\n    sys.exit(main())\n  File \"/venv/main/lib/python3.10/site-packages/accelerate/commands/accelerate_cli.py\", line 48, in main\n    args.func(args)\n  File \"/venv/main/lib/python3.10/site-packages/accelerate/commands/launch.py\", line 1088, in launch_command\n    multi_gpu_launcher(args)\n  File \"/venv/main/lib/python3.10/site-packages/accelerate/commands/launch.py\", line 733, in multi_gpu_launcher\n    distrib_run.run(args)\n  File \"/venv/main/lib/python3.10/site-packages/torch/distributed/run.py\", line 870, in run\n    elastic_launch(\n  File \"/venv/main/lib/python3.10/site-packages/torch/distributed/launcher/api.py\", line 132, in __call__\n    return launch_agent(self._config, self._entrypoint, list(args))\n  File \"/venv/main/lib/python3.10/site-packages/torch/distributed/launcher/api.py\", line 263, in launch_agent\n    raise ChildFailedError(\ntorch.distributed.elastic.multiprocessing.errors.ChildFailedError: \n============================================================\npython3 FAILED\n------------------------------------------------------------\nFailures:\n[1]:\n  time      : 2025-09-03_14:17:49\n  host      : 2fd62b2353f7\n  rank      : 1 (local_rank: 1)\n  exitcode  : 2 (pid: 312307)\n  error_file: <N/A>\n  traceback : To enable traceback see: https://pytorch.org/docs/stable/elastic/errors.html\n------------------------------------------------------------\nRoot Cause (first observed failure):\n[0]:\n  time      : 2025-09-03_14:17:49\n  host      : 2fd62b2353f7\n  rank      : 0 (local_rank: 0)\n  exitcode  : 2 (pid: 312306)\n  error_file: <N/A>\n  traceback : To enable traceback see: https://pytorch.org/docs/stable/elastic/errors.html\n============================================================\n"
    }
  }
}